<?xml version="1.0" ?>
<!-- =================================================================================== -->
<!-- |    This document was autogenerated by xacro from /home/gamewame/catkin_ws/src/robot_model_pkg/urdf/robot.xacro | -->
<!-- |    EDITING THIS FILE BY HAND IS NOT RECOMMENDED                                 | -->
<!-- =================================================================================== -->
<robot name="differential_drive_robot">
  <gazebo reference="body_link">
    <mu1>0.2</mu1>
    <mu2>0.2</mu2>
    <material>Gazebo/Red</material>
  </gazebo>
  <gazebo reference="wheel1_link">
    <mu1>0.2</mu1>
    <mu2>0.2</mu2>
    <material>Gazebo/Yellow</material>
  </gazebo>
  <gazebo reference="wheel2_link">
    <mu1>0.2</mu1>
    <mu2>0.2</mu2>
    <material>Gazebo/Yellow</material>
  </gazebo>
  <gazebo reference="wheel3_link">
    <mu1>0.2</mu1>
    <mu2>0.2</mu2>
    <material>Gazebo/Yellow</material>
  </gazebo>
  <gazebo reference="wheel4_link">
    <mu1>0.2</mu1>
    <mu2>0.2</mu2>
    <material>Gazebo/Yellow</material>
  </gazebo>
  <!-- Controller for the robot -->
  <gazebo>
    <plugin filename="libgazebo_ros_skid_steer_drive.so" name="skid_steer_drive_controller">
      <updateRate>100.0</updateRate>
      <robotNamespace> </robotNamespace>
      <!-- needs to be empty -->
      <leftFrontJoint>wheel4_joint</leftFrontJoint>
      <rightFrontJoint>wheel3_joint</rightFrontJoint>
      <leftRearJoint>wheel2_joint</leftRearJoint>
      <rightRearJoint>wheel1_joint</rightRearJoint>
      <wheelSeparation>0.7</wheelSeparation>
      <wheelDiameter>0.15</wheelDiameter>
      <!-- Maximum torque -->
      <torque>1000</torque>
      <commandTopic>cmd_vel</commandTopic>
      <odometryTopic>odom</odometryTopic>
      <odometryFrame>odom</odometryFrame>
      <robotBaseFrame>dummy</robotBaseFrame>
      <publishWheelTF>true</publishWheelTF>
      <publish0dom>true</publish0dom>
      <publishWheelJointState>true</publishWheelJointState>
      <!-- part required by Gazebo -->
      <covariance_x>0.0001</covariance_x>
      <covariance_y>0.0001</covariance_y>
      <covariance_yaw>0.01</covariance_yaw>
    </plugin>
  </gazebo>
  <!-- LINKS -->
  <link name="dummy">
</link>
  <joint name="dummy_joint" type="fixed">
    <parent link="dummy"/>
    <child link="body_link"/>
  </joint>
  <link name="body_link">
    <visual>
      <geometry>
        <box size="1 0.6 0.3"/>
      </geometry>
      <origin rpy="0 0 0" xyz="0 0 0"/>
    </visual>
    <collision>
      <geometry>
        <box size="1 0.6 0.3"/>
      </geometry>
      <origin rpy="0 0 0" xyz="0 0 0"/>
    </collision>
    <inertial>
      <origin rpy="0 0 0" xyz="0 0 0"/>
      <mass value="487.79999999999995"/>
      <inertia ixx="18.292499999999993" ixy="0" ixz="0" iyy="44.308499999999995" iyz="0" izz="55.283999999999985"/>
    </inertial>
  </link>
  <!-- Back Righ wheel -->
  <joint name="wheel1_joint" type="continuous">
    <parent link="body_link"/>
    <child link="wheel1_link"/>
    <origin rpy="0 0 0" xyz="-0.32 -0.35 $ {wheel_link_z_location}"/>
    <axis xyz="0 1 0"/>
    <limit effort="1000" velocity="1000"/>
    <dynamics damping="1.0" friction="1.0"/>
  </joint>
  <link name="wheel1_link">
    <visual>
      <origin rpy="1.570795 0 0" xyz="0 0 0"/>
      <geometry>
        <cylinder length="0.1" radius="0.15"/>
      </geometry>
    </visual>
    <collision>
      <origin rpy="1.570795 0 0" xyz="0 0 0"/>
      <geometry>
        <cylinder length="0.1" radius="0.15"/>
      </geometry>
    </collision>
    <inertial>
      <origin rpy="0 0 0" xyz="0 0 0"/>
      <mass value="127.70574122250001"/>
      <inertia ixx="0.8247662453953124" ixy="0.0" ixz="0.0" iyy="0.8247662453953124" iyz="0" izz="1.436689588753125"/>
    </inertial>
  </link>
  <!-- Back Left wheel -->
  <joint name="wheel2_joint" type="continuous">
    <parent link="body_link"/>
    <child link="wheel2_link"/>
    <origin rpy="0 0 0" xyz="-0.32 0.35 $ {wheel_link_z_location}"/>
    <axis xyz="0 1 0"/>
    <limit effort="1000" velocity="1000"/>
    <dynamics damping="1.0" friction="1.0"/>
  </joint>
  <link name="wheel2_link">
    <visual>
      <origin rpy="1.570795 0 0" xyz="0 0 0"/>
      <geometry>
        <cylinder length="0.1" radius="0.15"/>
      </geometry>
    </visual>
    <collision>
      <origin rpy="1.570795 0 0" xyz="0 0 0"/>
      <geometry>
        <cylinder length="0.1" radius="0.15"/>
      </geometry>
    </collision>
    <inertial>
      <origin rpy="0 0 0" xyz="0 0 0"/>
      <mass value="127.70574122250001"/>
      <inertia ixx="0.8247662453953124" ixy="0.0" ixz="0.0" iyy="0.8247662453953124" iyz="0" izz="1.436689588753125"/>
    </inertial>
  </link>
  <!-- Front Right wheel -->
  <joint name="wheel3_joint" type="continuous">
    <parent link="body_link"/>
    <child link="wheel3_link"/>
    <origin rpy="0 0 0" xyz="0.32 -0.35 $ {wheel_link_z_location}"/>
    <axis xyz="0 1 0"/>
    <limit effort="1000" velocity="1000"/>
    <dynamics damping="1.0" friction="1.0"/>
  </joint>
  <link name="wheel3_link">
    <visual>
      <origin rpy="1.570795 0 0" xyz="0 0 0"/>
      <geometry>
        <cylinder length="0.1" radius="0.15"/>
      </geometry>
    </visual>
    <collision>
      <origin rpy="1.570795 0 0" xyz="0 0 0"/>
      <geometry>
        <cylinder length="0.1" radius="0.15"/>
      </geometry>
    </collision>
    <inertial>
      <origin rpy="0 0 0" xyz="0 0 0"/>
      <mass value="127.70574122250001"/>
      <inertia ixx="0.8247662453953124" ixy="0.0" ixz="0.0" iyy="0.8247662453953124" iyz="0" izz="1.436689588753125"/>
    </inertial>
  </link>
  <!-- Front Left wheel -->
  <joint name="wheel4_joint" type="continuous">
    <parent link="body_link"/>
    <child link="wheel4_link"/>
    <origin rpy="0 0 0" xyz="0.32 0.35 $ {wheel_link_z_location}"/>
    <axis xyz="0 1 0"/>
    <limit effort="1000" velocity="1000"/>
    <dynamics damping="1.0" friction="1.0"/>
  </joint>
  <link name="wheel4_link">
    <visual>
      <origin rpy="1.570795 0 0" xyz="0 0 0"/>
      <geometry>
        <cylinder length="0.1" radius="0.15"/>
      </geometry>
    </visual>
    <collision>
      <origin rpy="1.570795 0 0" xyz="0 0 0"/>
      <geometry>
        <cylinder length="0.1" radius="0.15"/>
      </geometry>
    </collision>
    <inertial>
      <origin rpy="0 0 0" xyz="0 0 0"/>
      <mass value="127.70574122250001"/>
      <inertia ixx="0.8247662453953124" ixy="0.0" ixz="0.0" iyy="0.8247662453953124" iyz="0" izz="1.436689588753125"/>
    </inertial>
  </link>
</robot>
